2020-04-21 12:21:52,607 - flask.app - ERROR - Exception on / [GET]
Traceback (most recent call last):
  File "/Users/13ob0/projects/flask/myblog/env_blog/lib/python3.7/site-packages/sqlalchemy/engine/base.py", line 1193, in _execute_context
    context)
  File "/Users/13ob0/projects/flask/myblog/env_blog/lib/python3.7/site-packages/sqlalchemy/engine/default.py", line 509, in do_execute
    cursor.execute(statement, parameters)
sqlite3.OperationalError: no such column: post.can_comment

The above exception was the direct cause of the following exception:

Traceback (most recent call last):
  File "/Users/13ob0/projects/flask/myblog/env_blog/lib/python3.7/site-packages/flask/app.py", line 2292, in wsgi_app
    response = self.full_dispatch_request()
  File "/Users/13ob0/projects/flask/myblog/env_blog/lib/python3.7/site-packages/flask/app.py", line 1815, in full_dispatch_request
    rv = self.handle_user_exception(e)
  File "/Users/13ob0/projects/flask/myblog/env_blog/lib/python3.7/site-packages/flask/app.py", line 1718, in handle_user_exception
    reraise(exc_type, exc_value, tb)
  File "/Users/13ob0/projects/flask/myblog/env_blog/lib/python3.7/site-packages/flask/_compat.py", line 35, in reraise
    raise value
  File "/Users/13ob0/projects/flask/myblog/env_blog/lib/python3.7/site-packages/flask/app.py", line 1813, in full_dispatch_request
    rv = self.dispatch_request()
  File "/Users/13ob0/projects/flask/myblog/env_blog/lib/python3.7/site-packages/flask/app.py", line 1799, in dispatch_request
    return self.view_functions[rule.endpoint](**req.view_args)
  File "/Users/13ob0/projects/flask/myblog/myblog/blueprints/blog.py", line 24, in index
    pagination = Post.query.order_by(Post.timestamp.desc()).paginate(page, per_page=per_page)
  File "/Users/13ob0/projects/flask/myblog/env_blog/lib/python3.7/site-packages/flask_sqlalchemy/__init__.py", line 491, in paginate
    items = self.limit(per_page).offset((page - 1) * per_page).all()
  File "/Users/13ob0/projects/flask/myblog/env_blog/lib/python3.7/site-packages/sqlalchemy/orm/query.py", line 2836, in all
    return list(self)
  File "/Users/13ob0/projects/flask/myblog/env_blog/lib/python3.7/site-packages/sqlalchemy/orm/query.py", line 2988, in __iter__
    return self._execute_and_instances(context)
  File "/Users/13ob0/projects/flask/myblog/env_blog/lib/python3.7/site-packages/sqlalchemy/orm/query.py", line 3011, in _execute_and_instances
    result = conn.execute(querycontext.statement, self._params)
  File "/Users/13ob0/projects/flask/myblog/env_blog/lib/python3.7/site-packages/sqlalchemy/engine/base.py", line 948, in execute
    return meth(self, multiparams, params)
  File "/Users/13ob0/projects/flask/myblog/env_blog/lib/python3.7/site-packages/sqlalchemy/sql/elements.py", line 269, in _execute_on_connection
    return connection._execute_clauseelement(self, multiparams, params)
  File "/Users/13ob0/projects/flask/myblog/env_blog/lib/python3.7/site-packages/sqlalchemy/engine/base.py", line 1060, in _execute_clauseelement
    compiled_sql, distilled_params
  File "/Users/13ob0/projects/flask/myblog/env_blog/lib/python3.7/site-packages/sqlalchemy/engine/base.py", line 1200, in _execute_context
    context)
  File "/Users/13ob0/projects/flask/myblog/env_blog/lib/python3.7/site-packages/sqlalchemy/engine/base.py", line 1413, in _handle_dbapi_exception
    exc_info
  File "/Users/13ob0/projects/flask/myblog/env_blog/lib/python3.7/site-packages/sqlalchemy/util/compat.py", line 265, in raise_from_cause
    reraise(type(exception), exception, tb=exc_tb, cause=cause)
  File "/Users/13ob0/projects/flask/myblog/env_blog/lib/python3.7/site-packages/sqlalchemy/util/compat.py", line 248, in reraise
    raise value.with_traceback(tb)
  File "/Users/13ob0/projects/flask/myblog/env_blog/lib/python3.7/site-packages/sqlalchemy/engine/base.py", line 1193, in _execute_context
    context)
  File "/Users/13ob0/projects/flask/myblog/env_blog/lib/python3.7/site-packages/sqlalchemy/engine/default.py", line 509, in do_execute
    cursor.execute(statement, parameters)
sqlalchemy.exc.OperationalError: (sqlite3.OperationalError) no such column: post.can_comment [SQL: 'SELECT post.id AS post_id, post.title AS post_title, post.body AS post_body, post.timestamp AS post_timestamp, post.can_comment AS post_can_comment, post.category_id AS post_category_id \nFROM post ORDER BY post.timestamp DESC\n LIMIT ? OFFSET ?'] [parameters: (10, 0)] (Background on this error at: http://sqlalche.me/e/e3q8)
2020-04-21 12:21:52,683 - flask.app - ERROR - Exception on / [GET]
Traceback (most recent call last):
  File "/Users/13ob0/projects/flask/myblog/env_blog/lib/python3.7/site-packages/sqlalchemy/engine/base.py", line 1193, in _execute_context
    context)
  File "/Users/13ob0/projects/flask/myblog/env_blog/lib/python3.7/site-packages/sqlalchemy/engine/default.py", line 509, in do_execute
    cursor.execute(statement, parameters)
sqlite3.OperationalError: no such column: post.can_comment

The above exception was the direct cause of the following exception:

Traceback (most recent call last):
  File "/Users/13ob0/projects/flask/myblog/env_blog/lib/python3.7/site-packages/flask/app.py", line 2292, in wsgi_app
    response = self.full_dispatch_request()
  File "/Users/13ob0/projects/flask/myblog/env_blog/lib/python3.7/site-packages/flask/app.py", line 1815, in full_dispatch_request
    rv = self.handle_user_exception(e)
  File "/Users/13ob0/projects/flask/myblog/env_blog/lib/python3.7/site-packages/flask/app.py", line 1718, in handle_user_exception
    reraise(exc_type, exc_value, tb)
  File "/Users/13ob0/projects/flask/myblog/env_blog/lib/python3.7/site-packages/flask/_compat.py", line 35, in reraise
    raise value
  File "/Users/13ob0/projects/flask/myblog/env_blog/lib/python3.7/site-packages/flask/app.py", line 1813, in full_dispatch_request
    rv = self.dispatch_request()
  File "/Users/13ob0/projects/flask/myblog/env_blog/lib/python3.7/site-packages/flask/app.py", line 1799, in dispatch_request
    return self.view_functions[rule.endpoint](**req.view_args)
  File "/Users/13ob0/projects/flask/myblog/myblog/blueprints/blog.py", line 24, in index
    pagination = Post.query.order_by(Post.timestamp.desc()).paginate(page, per_page=per_page)
  File "/Users/13ob0/projects/flask/myblog/env_blog/lib/python3.7/site-packages/flask_sqlalchemy/__init__.py", line 491, in paginate
    items = self.limit(per_page).offset((page - 1) * per_page).all()
  File "/Users/13ob0/projects/flask/myblog/env_blog/lib/python3.7/site-packages/sqlalchemy/orm/query.py", line 2836, in all
    return list(self)
  File "/Users/13ob0/projects/flask/myblog/env_blog/lib/python3.7/site-packages/sqlalchemy/orm/query.py", line 2988, in __iter__
    return self._execute_and_instances(context)
  File "/Users/13ob0/projects/flask/myblog/env_blog/lib/python3.7/site-packages/sqlalchemy/orm/query.py", line 3011, in _execute_and_instances
    result = conn.execute(querycontext.statement, self._params)
  File "/Users/13ob0/projects/flask/myblog/env_blog/lib/python3.7/site-packages/sqlalchemy/engine/base.py", line 948, in execute
    return meth(self, multiparams, params)
  File "/Users/13ob0/projects/flask/myblog/env_blog/lib/python3.7/site-packages/sqlalchemy/sql/elements.py", line 269, in _execute_on_connection
    return connection._execute_clauseelement(self, multiparams, params)
  File "/Users/13ob0/projects/flask/myblog/env_blog/lib/python3.7/site-packages/sqlalchemy/engine/base.py", line 1060, in _execute_clauseelement
    compiled_sql, distilled_params
  File "/Users/13ob0/projects/flask/myblog/env_blog/lib/python3.7/site-packages/sqlalchemy/engine/base.py", line 1200, in _execute_context
    context)
  File "/Users/13ob0/projects/flask/myblog/env_blog/lib/python3.7/site-packages/sqlalchemy/engine/base.py", line 1413, in _handle_dbapi_exception
    exc_info
  File "/Users/13ob0/projects/flask/myblog/env_blog/lib/python3.7/site-packages/sqlalchemy/util/compat.py", line 265, in raise_from_cause
    reraise(type(exception), exception, tb=exc_tb, cause=cause)
  File "/Users/13ob0/projects/flask/myblog/env_blog/lib/python3.7/site-packages/sqlalchemy/util/compat.py", line 248, in reraise
    raise value.with_traceback(tb)
  File "/Users/13ob0/projects/flask/myblog/env_blog/lib/python3.7/site-packages/sqlalchemy/engine/base.py", line 1193, in _execute_context
    context)
  File "/Users/13ob0/projects/flask/myblog/env_blog/lib/python3.7/site-packages/sqlalchemy/engine/default.py", line 509, in do_execute
    cursor.execute(statement, parameters)
sqlalchemy.exc.OperationalError: (sqlite3.OperationalError) no such column: post.can_comment [SQL: 'SELECT post.id AS post_id, post.title AS post_title, post.body AS post_body, post.timestamp AS post_timestamp, post.can_comment AS post_can_comment, post.category_id AS post_category_id \nFROM post ORDER BY post.timestamp DESC\n LIMIT ? OFFSET ?'] [parameters: (10, 0)] (Background on this error at: http://sqlalche.me/e/e3q8)
2020-04-21 12:21:52,701 - flask.app - ERROR - Exception on / [GET]
Traceback (most recent call last):
  File "/Users/13ob0/projects/flask/myblog/env_blog/lib/python3.7/site-packages/sqlalchemy/engine/base.py", line 1193, in _execute_context
    context)
  File "/Users/13ob0/projects/flask/myblog/env_blog/lib/python3.7/site-packages/sqlalchemy/engine/default.py", line 509, in do_execute
    cursor.execute(statement, parameters)
sqlite3.OperationalError: no such column: post.can_comment

The above exception was the direct cause of the following exception:

Traceback (most recent call last):
  File "/Users/13ob0/projects/flask/myblog/env_blog/lib/python3.7/site-packages/flask/app.py", line 2292, in wsgi_app
    response = self.full_dispatch_request()
  File "/Users/13ob0/projects/flask/myblog/env_blog/lib/python3.7/site-packages/flask/app.py", line 1815, in full_dispatch_request
    rv = self.handle_user_exception(e)
  File "/Users/13ob0/projects/flask/myblog/env_blog/lib/python3.7/site-packages/flask/app.py", line 1718, in handle_user_exception
    reraise(exc_type, exc_value, tb)
  File "/Users/13ob0/projects/flask/myblog/env_blog/lib/python3.7/site-packages/flask/_compat.py", line 35, in reraise
    raise value
  File "/Users/13ob0/projects/flask/myblog/env_blog/lib/python3.7/site-packages/flask/app.py", line 1813, in full_dispatch_request
    rv = self.dispatch_request()
  File "/Users/13ob0/projects/flask/myblog/env_blog/lib/python3.7/site-packages/flask/app.py", line 1799, in dispatch_request
    return self.view_functions[rule.endpoint](**req.view_args)
  File "/Users/13ob0/projects/flask/myblog/myblog/blueprints/blog.py", line 24, in index
    pagination = Post.query.order_by(Post.timestamp.desc()).paginate(page, per_page=per_page)
  File "/Users/13ob0/projects/flask/myblog/env_blog/lib/python3.7/site-packages/flask_sqlalchemy/__init__.py", line 491, in paginate
    items = self.limit(per_page).offset((page - 1) * per_page).all()
  File "/Users/13ob0/projects/flask/myblog/env_blog/lib/python3.7/site-packages/sqlalchemy/orm/query.py", line 2836, in all
    return list(self)
  File "/Users/13ob0/projects/flask/myblog/env_blog/lib/python3.7/site-packages/sqlalchemy/orm/query.py", line 2988, in __iter__
    return self._execute_and_instances(context)
  File "/Users/13ob0/projects/flask/myblog/env_blog/lib/python3.7/site-packages/sqlalchemy/orm/query.py", line 3011, in _execute_and_instances
    result = conn.execute(querycontext.statement, self._params)
  File "/Users/13ob0/projects/flask/myblog/env_blog/lib/python3.7/site-packages/sqlalchemy/engine/base.py", line 948, in execute
    return meth(self, multiparams, params)
  File "/Users/13ob0/projects/flask/myblog/env_blog/lib/python3.7/site-packages/sqlalchemy/sql/elements.py", line 269, in _execute_on_connection
    return connection._execute_clauseelement(self, multiparams, params)
  File "/Users/13ob0/projects/flask/myblog/env_blog/lib/python3.7/site-packages/sqlalchemy/engine/base.py", line 1060, in _execute_clauseelement
    compiled_sql, distilled_params
  File "/Users/13ob0/projects/flask/myblog/env_blog/lib/python3.7/site-packages/sqlalchemy/engine/base.py", line 1200, in _execute_context
    context)
  File "/Users/13ob0/projects/flask/myblog/env_blog/lib/python3.7/site-packages/sqlalchemy/engine/base.py", line 1413, in _handle_dbapi_exception
    exc_info
  File "/Users/13ob0/projects/flask/myblog/env_blog/lib/python3.7/site-packages/sqlalchemy/util/compat.py", line 265, in raise_from_cause
    reraise(type(exception), exception, tb=exc_tb, cause=cause)
  File "/Users/13ob0/projects/flask/myblog/env_blog/lib/python3.7/site-packages/sqlalchemy/util/compat.py", line 248, in reraise
    raise value.with_traceback(tb)
  File "/Users/13ob0/projects/flask/myblog/env_blog/lib/python3.7/site-packages/sqlalchemy/engine/base.py", line 1193, in _execute_context
    context)
  File "/Users/13ob0/projects/flask/myblog/env_blog/lib/python3.7/site-packages/sqlalchemy/engine/default.py", line 509, in do_execute
    cursor.execute(statement, parameters)
sqlalchemy.exc.OperationalError: (sqlite3.OperationalError) no such column: post.can_comment [SQL: 'SELECT post.id AS post_id, post.title AS post_title, post.body AS post_body, post.timestamp AS post_timestamp, post.can_comment AS post_can_comment, post.category_id AS post_category_id \nFROM post ORDER BY post.timestamp DESC\n LIMIT ? OFFSET ?'] [parameters: (10, 0)] (Background on this error at: http://sqlalche.me/e/e3q8)
2020-04-21 12:21:58,320 - flask.app - ERROR - Exception on / [GET]
Traceback (most recent call last):
  File "/Users/13ob0/projects/flask/myblog/env_blog/lib/python3.7/site-packages/sqlalchemy/engine/base.py", line 1193, in _execute_context
    context)
  File "/Users/13ob0/projects/flask/myblog/env_blog/lib/python3.7/site-packages/sqlalchemy/engine/default.py", line 509, in do_execute
    cursor.execute(statement, parameters)
sqlite3.OperationalError: no such column: post.can_comment

The above exception was the direct cause of the following exception:

Traceback (most recent call last):
  File "/Users/13ob0/projects/flask/myblog/env_blog/lib/python3.7/site-packages/flask/app.py", line 2292, in wsgi_app
    response = self.full_dispatch_request()
  File "/Users/13ob0/projects/flask/myblog/env_blog/lib/python3.7/site-packages/flask/app.py", line 1815, in full_dispatch_request
    rv = self.handle_user_exception(e)
  File "/Users/13ob0/projects/flask/myblog/env_blog/lib/python3.7/site-packages/flask/app.py", line 1718, in handle_user_exception
    reraise(exc_type, exc_value, tb)
  File "/Users/13ob0/projects/flask/myblog/env_blog/lib/python3.7/site-packages/flask/_compat.py", line 35, in reraise
    raise value
  File "/Users/13ob0/projects/flask/myblog/env_blog/lib/python3.7/site-packages/flask/app.py", line 1813, in full_dispatch_request
    rv = self.dispatch_request()
  File "/Users/13ob0/projects/flask/myblog/env_blog/lib/python3.7/site-packages/flask/app.py", line 1799, in dispatch_request
    return self.view_functions[rule.endpoint](**req.view_args)
  File "/Users/13ob0/projects/flask/myblog/myblog/blueprints/blog.py", line 24, in index
    pagination = Post.query.order_by(Post.timestamp.desc()).paginate(page, per_page=per_page)
  File "/Users/13ob0/projects/flask/myblog/env_blog/lib/python3.7/site-packages/flask_sqlalchemy/__init__.py", line 491, in paginate
    items = self.limit(per_page).offset((page - 1) * per_page).all()
  File "/Users/13ob0/projects/flask/myblog/env_blog/lib/python3.7/site-packages/sqlalchemy/orm/query.py", line 2836, in all
    return list(self)
  File "/Users/13ob0/projects/flask/myblog/env_blog/lib/python3.7/site-packages/sqlalchemy/orm/query.py", line 2988, in __iter__
    return self._execute_and_instances(context)
  File "/Users/13ob0/projects/flask/myblog/env_blog/lib/python3.7/site-packages/sqlalchemy/orm/query.py", line 3011, in _execute_and_instances
    result = conn.execute(querycontext.statement, self._params)
  File "/Users/13ob0/projects/flask/myblog/env_blog/lib/python3.7/site-packages/sqlalchemy/engine/base.py", line 948, in execute
    return meth(self, multiparams, params)
  File "/Users/13ob0/projects/flask/myblog/env_blog/lib/python3.7/site-packages/sqlalchemy/sql/elements.py", line 269, in _execute_on_connection
    return connection._execute_clauseelement(self, multiparams, params)
  File "/Users/13ob0/projects/flask/myblog/env_blog/lib/python3.7/site-packages/sqlalchemy/engine/base.py", line 1060, in _execute_clauseelement
    compiled_sql, distilled_params
  File "/Users/13ob0/projects/flask/myblog/env_blog/lib/python3.7/site-packages/sqlalchemy/engine/base.py", line 1200, in _execute_context
    context)
  File "/Users/13ob0/projects/flask/myblog/env_blog/lib/python3.7/site-packages/sqlalchemy/engine/base.py", line 1413, in _handle_dbapi_exception
    exc_info
  File "/Users/13ob0/projects/flask/myblog/env_blog/lib/python3.7/site-packages/sqlalchemy/util/compat.py", line 265, in raise_from_cause
    reraise(type(exception), exception, tb=exc_tb, cause=cause)
  File "/Users/13ob0/projects/flask/myblog/env_blog/lib/python3.7/site-packages/sqlalchemy/util/compat.py", line 248, in reraise
    raise value.with_traceback(tb)
  File "/Users/13ob0/projects/flask/myblog/env_blog/lib/python3.7/site-packages/sqlalchemy/engine/base.py", line 1193, in _execute_context
    context)
  File "/Users/13ob0/projects/flask/myblog/env_blog/lib/python3.7/site-packages/sqlalchemy/engine/default.py", line 509, in do_execute
    cursor.execute(statement, parameters)
sqlalchemy.exc.OperationalError: (sqlite3.OperationalError) no such column: post.can_comment [SQL: 'SELECT post.id AS post_id, post.title AS post_title, post.body AS post_body, post.timestamp AS post_timestamp, post.can_comment AS post_can_comment, post.category_id AS post_category_id \nFROM post ORDER BY post.timestamp DESC\n LIMIT ? OFFSET ?'] [parameters: (10, 0)] (Background on this error at: http://sqlalche.me/e/e3q8)
2020-04-21 12:21:58,337 - flask.app - ERROR - Exception on / [GET]
Traceback (most recent call last):
  File "/Users/13ob0/projects/flask/myblog/env_blog/lib/python3.7/site-packages/sqlalchemy/engine/base.py", line 1193, in _execute_context
    context)
  File "/Users/13ob0/projects/flask/myblog/env_blog/lib/python3.7/site-packages/sqlalchemy/engine/default.py", line 509, in do_execute
    cursor.execute(statement, parameters)
sqlite3.OperationalError: no such column: post.can_comment

The above exception was the direct cause of the following exception:

Traceback (most recent call last):
  File "/Users/13ob0/projects/flask/myblog/env_blog/lib/python3.7/site-packages/flask/app.py", line 2292, in wsgi_app
    response = self.full_dispatch_request()
  File "/Users/13ob0/projects/flask/myblog/env_blog/lib/python3.7/site-packages/flask/app.py", line 1815, in full_dispatch_request
    rv = self.handle_user_exception(e)
  File "/Users/13ob0/projects/flask/myblog/env_blog/lib/python3.7/site-packages/flask/app.py", line 1718, in handle_user_exception
    reraise(exc_type, exc_value, tb)
  File "/Users/13ob0/projects/flask/myblog/env_blog/lib/python3.7/site-packages/flask/_compat.py", line 35, in reraise
    raise value
  File "/Users/13ob0/projects/flask/myblog/env_blog/lib/python3.7/site-packages/flask/app.py", line 1813, in full_dispatch_request
    rv = self.dispatch_request()
  File "/Users/13ob0/projects/flask/myblog/env_blog/lib/python3.7/site-packages/flask/app.py", line 1799, in dispatch_request
    return self.view_functions[rule.endpoint](**req.view_args)
  File "/Users/13ob0/projects/flask/myblog/myblog/blueprints/blog.py", line 24, in index
    pagination = Post.query.order_by(Post.timestamp.desc()).paginate(page, per_page=per_page)
  File "/Users/13ob0/projects/flask/myblog/env_blog/lib/python3.7/site-packages/flask_sqlalchemy/__init__.py", line 491, in paginate
    items = self.limit(per_page).offset((page - 1) * per_page).all()
  File "/Users/13ob0/projects/flask/myblog/env_blog/lib/python3.7/site-packages/sqlalchemy/orm/query.py", line 2836, in all
    return list(self)
  File "/Users/13ob0/projects/flask/myblog/env_blog/lib/python3.7/site-packages/sqlalchemy/orm/query.py", line 2988, in __iter__
    return self._execute_and_instances(context)
  File "/Users/13ob0/projects/flask/myblog/env_blog/lib/python3.7/site-packages/sqlalchemy/orm/query.py", line 3011, in _execute_and_instances
    result = conn.execute(querycontext.statement, self._params)
  File "/Users/13ob0/projects/flask/myblog/env_blog/lib/python3.7/site-packages/sqlalchemy/engine/base.py", line 948, in execute
    return meth(self, multiparams, params)
  File "/Users/13ob0/projects/flask/myblog/env_blog/lib/python3.7/site-packages/sqlalchemy/sql/elements.py", line 269, in _execute_on_connection
    return connection._execute_clauseelement(self, multiparams, params)
  File "/Users/13ob0/projects/flask/myblog/env_blog/lib/python3.7/site-packages/sqlalchemy/engine/base.py", line 1060, in _execute_clauseelement
    compiled_sql, distilled_params
  File "/Users/13ob0/projects/flask/myblog/env_blog/lib/python3.7/site-packages/sqlalchemy/engine/base.py", line 1200, in _execute_context
    context)
  File "/Users/13ob0/projects/flask/myblog/env_blog/lib/python3.7/site-packages/sqlalchemy/engine/base.py", line 1413, in _handle_dbapi_exception
    exc_info
  File "/Users/13ob0/projects/flask/myblog/env_blog/lib/python3.7/site-packages/sqlalchemy/util/compat.py", line 265, in raise_from_cause
    reraise(type(exception), exception, tb=exc_tb, cause=cause)
  File "/Users/13ob0/projects/flask/myblog/env_blog/lib/python3.7/site-packages/sqlalchemy/util/compat.py", line 248, in reraise
    raise value.with_traceback(tb)
  File "/Users/13ob0/projects/flask/myblog/env_blog/lib/python3.7/site-packages/sqlalchemy/engine/base.py", line 1193, in _execute_context
    context)
  File "/Users/13ob0/projects/flask/myblog/env_blog/lib/python3.7/site-packages/sqlalchemy/engine/default.py", line 509, in do_execute
    cursor.execute(statement, parameters)
sqlalchemy.exc.OperationalError: (sqlite3.OperationalError) no such column: post.can_comment [SQL: 'SELECT post.id AS post_id, post.title AS post_title, post.body AS post_body, post.timestamp AS post_timestamp, post.can_comment AS post_can_comment, post.category_id AS post_category_id \nFROM post ORDER BY post.timestamp DESC\n LIMIT ? OFFSET ?'] [parameters: (10, 0)] (Background on this error at: http://sqlalche.me/e/e3q8)
2020-04-21 12:21:58,352 - flask.app - ERROR - Exception on / [GET]
Traceback (most recent call last):
  File "/Users/13ob0/projects/flask/myblog/env_blog/lib/python3.7/site-packages/sqlalchemy/engine/base.py", line 1193, in _execute_context
    context)
  File "/Users/13ob0/projects/flask/myblog/env_blog/lib/python3.7/site-packages/sqlalchemy/engine/default.py", line 509, in do_execute
    cursor.execute(statement, parameters)
sqlite3.OperationalError: no such column: post.can_comment

The above exception was the direct cause of the following exception:

Traceback (most recent call last):
  File "/Users/13ob0/projects/flask/myblog/env_blog/lib/python3.7/site-packages/flask/app.py", line 2292, in wsgi_app
    response = self.full_dispatch_request()
  File "/Users/13ob0/projects/flask/myblog/env_blog/lib/python3.7/site-packages/flask/app.py", line 1815, in full_dispatch_request
    rv = self.handle_user_exception(e)
  File "/Users/13ob0/projects/flask/myblog/env_blog/lib/python3.7/site-packages/flask/app.py", line 1718, in handle_user_exception
    reraise(exc_type, exc_value, tb)
  File "/Users/13ob0/projects/flask/myblog/env_blog/lib/python3.7/site-packages/flask/_compat.py", line 35, in reraise
    raise value
  File "/Users/13ob0/projects/flask/myblog/env_blog/lib/python3.7/site-packages/flask/app.py", line 1813, in full_dispatch_request
    rv = self.dispatch_request()
  File "/Users/13ob0/projects/flask/myblog/env_blog/lib/python3.7/site-packages/flask/app.py", line 1799, in dispatch_request
    return self.view_functions[rule.endpoint](**req.view_args)
  File "/Users/13ob0/projects/flask/myblog/myblog/blueprints/blog.py", line 24, in index
    pagination = Post.query.order_by(Post.timestamp.desc()).paginate(page, per_page=per_page)
  File "/Users/13ob0/projects/flask/myblog/env_blog/lib/python3.7/site-packages/flask_sqlalchemy/__init__.py", line 491, in paginate
    items = self.limit(per_page).offset((page - 1) * per_page).all()
  File "/Users/13ob0/projects/flask/myblog/env_blog/lib/python3.7/site-packages/sqlalchemy/orm/query.py", line 2836, in all
    return list(self)
  File "/Users/13ob0/projects/flask/myblog/env_blog/lib/python3.7/site-packages/sqlalchemy/orm/query.py", line 2988, in __iter__
    return self._execute_and_instances(context)
  File "/Users/13ob0/projects/flask/myblog/env_blog/lib/python3.7/site-packages/sqlalchemy/orm/query.py", line 3011, in _execute_and_instances
    result = conn.execute(querycontext.statement, self._params)
  File "/Users/13ob0/projects/flask/myblog/env_blog/lib/python3.7/site-packages/sqlalchemy/engine/base.py", line 948, in execute
    return meth(self, multiparams, params)
  File "/Users/13ob0/projects/flask/myblog/env_blog/lib/python3.7/site-packages/sqlalchemy/sql/elements.py", line 269, in _execute_on_connection
    return connection._execute_clauseelement(self, multiparams, params)
  File "/Users/13ob0/projects/flask/myblog/env_blog/lib/python3.7/site-packages/sqlalchemy/engine/base.py", line 1060, in _execute_clauseelement
    compiled_sql, distilled_params
  File "/Users/13ob0/projects/flask/myblog/env_blog/lib/python3.7/site-packages/sqlalchemy/engine/base.py", line 1200, in _execute_context
    context)
  File "/Users/13ob0/projects/flask/myblog/env_blog/lib/python3.7/site-packages/sqlalchemy/engine/base.py", line 1413, in _handle_dbapi_exception
    exc_info
  File "/Users/13ob0/projects/flask/myblog/env_blog/lib/python3.7/site-packages/sqlalchemy/util/compat.py", line 265, in raise_from_cause
    reraise(type(exception), exception, tb=exc_tb, cause=cause)
  File "/Users/13ob0/projects/flask/myblog/env_blog/lib/python3.7/site-packages/sqlalchemy/util/compat.py", line 248, in reraise
    raise value.with_traceback(tb)
  File "/Users/13ob0/projects/flask/myblog/env_blog/lib/python3.7/site-packages/sqlalchemy/engine/base.py", line 1193, in _execute_context
    context)
  File "/Users/13ob0/projects/flask/myblog/env_blog/lib/python3.7/site-packages/sqlalchemy/engine/default.py", line 509, in do_execute
    cursor.execute(statement, parameters)
sqlalchemy.exc.OperationalError: (sqlite3.OperationalError) no such column: post.can_comment [SQL: 'SELECT post.id AS post_id, post.title AS post_title, post.body AS post_body, post.timestamp AS post_timestamp, post.can_comment AS post_can_comment, post.category_id AS post_category_id \nFROM post ORDER BY post.timestamp DESC\n LIMIT ? OFFSET ?'] [parameters: (10, 0)] (Background on this error at: http://sqlalche.me/e/e3q8)
2020-04-21 12:22:23,836 - flask.app - ERROR - Exception on / [GET]
Traceback (most recent call last):
  File "/Users/13ob0/projects/flask/myblog/env_blog/lib/python3.7/site-packages/sqlalchemy/engine/base.py", line 1193, in _execute_context
    context)
  File "/Users/13ob0/projects/flask/myblog/env_blog/lib/python3.7/site-packages/sqlalchemy/engine/default.py", line 509, in do_execute
    cursor.execute(statement, parameters)
sqlite3.OperationalError: no such table: post

The above exception was the direct cause of the following exception:

Traceback (most recent call last):
  File "/Users/13ob0/projects/flask/myblog/env_blog/lib/python3.7/site-packages/flask/app.py", line 2292, in wsgi_app
    response = self.full_dispatch_request()
  File "/Users/13ob0/projects/flask/myblog/env_blog/lib/python3.7/site-packages/flask/app.py", line 1815, in full_dispatch_request
    rv = self.handle_user_exception(e)
  File "/Users/13ob0/projects/flask/myblog/env_blog/lib/python3.7/site-packages/flask/app.py", line 1718, in handle_user_exception
    reraise(exc_type, exc_value, tb)
  File "/Users/13ob0/projects/flask/myblog/env_blog/lib/python3.7/site-packages/flask/_compat.py", line 35, in reraise
    raise value
  File "/Users/13ob0/projects/flask/myblog/env_blog/lib/python3.7/site-packages/flask/app.py", line 1813, in full_dispatch_request
    rv = self.dispatch_request()
  File "/Users/13ob0/projects/flask/myblog/env_blog/lib/python3.7/site-packages/flask/app.py", line 1799, in dispatch_request
    return self.view_functions[rule.endpoint](**req.view_args)
  File "/Users/13ob0/projects/flask/myblog/myblog/blueprints/blog.py", line 24, in index
    pagination = Post.query.order_by(Post.timestamp.desc()).paginate(page, per_page=per_page)
  File "/Users/13ob0/projects/flask/myblog/env_blog/lib/python3.7/site-packages/flask_sqlalchemy/__init__.py", line 491, in paginate
    items = self.limit(per_page).offset((page - 1) * per_page).all()
  File "/Users/13ob0/projects/flask/myblog/env_blog/lib/python3.7/site-packages/sqlalchemy/orm/query.py", line 2836, in all
    return list(self)
  File "/Users/13ob0/projects/flask/myblog/env_blog/lib/python3.7/site-packages/sqlalchemy/orm/query.py", line 2988, in __iter__
    return self._execute_and_instances(context)
  File "/Users/13ob0/projects/flask/myblog/env_blog/lib/python3.7/site-packages/sqlalchemy/orm/query.py", line 3011, in _execute_and_instances
    result = conn.execute(querycontext.statement, self._params)
  File "/Users/13ob0/projects/flask/myblog/env_blog/lib/python3.7/site-packages/sqlalchemy/engine/base.py", line 948, in execute
    return meth(self, multiparams, params)
  File "/Users/13ob0/projects/flask/myblog/env_blog/lib/python3.7/site-packages/sqlalchemy/sql/elements.py", line 269, in _execute_on_connection
    return connection._execute_clauseelement(self, multiparams, params)
  File "/Users/13ob0/projects/flask/myblog/env_blog/lib/python3.7/site-packages/sqlalchemy/engine/base.py", line 1060, in _execute_clauseelement
    compiled_sql, distilled_params
  File "/Users/13ob0/projects/flask/myblog/env_blog/lib/python3.7/site-packages/sqlalchemy/engine/base.py", line 1200, in _execute_context
    context)
  File "/Users/13ob0/projects/flask/myblog/env_blog/lib/python3.7/site-packages/sqlalchemy/engine/base.py", line 1413, in _handle_dbapi_exception
    exc_info
  File "/Users/13ob0/projects/flask/myblog/env_blog/lib/python3.7/site-packages/sqlalchemy/util/compat.py", line 265, in raise_from_cause
    reraise(type(exception), exception, tb=exc_tb, cause=cause)
  File "/Users/13ob0/projects/flask/myblog/env_blog/lib/python3.7/site-packages/sqlalchemy/util/compat.py", line 248, in reraise
    raise value.with_traceback(tb)
  File "/Users/13ob0/projects/flask/myblog/env_blog/lib/python3.7/site-packages/sqlalchemy/engine/base.py", line 1193, in _execute_context
    context)
  File "/Users/13ob0/projects/flask/myblog/env_blog/lib/python3.7/site-packages/sqlalchemy/engine/default.py", line 509, in do_execute
    cursor.execute(statement, parameters)
sqlalchemy.exc.OperationalError: (sqlite3.OperationalError) no such table: post [SQL: 'SELECT post.id AS post_id, post.title AS post_title, post.body AS post_body, post.timestamp AS post_timestamp, post.can_comment AS post_can_comment, post.category_id AS post_category_id \nFROM post ORDER BY post.timestamp DESC\n LIMIT ? OFFSET ?'] [parameters: (10, 0)] (Background on this error at: http://sqlalche.me/e/e3q8)
2020-04-21 12:23:02,253 - flask.app - ERROR - Exception on / [GET]
Traceback (most recent call last):
  File "/Users/13ob0/projects/flask/myblog/env_blog/lib/python3.7/site-packages/flask/app.py", line 2292, in wsgi_app
    response = self.full_dispatch_request()
  File "/Users/13ob0/projects/flask/myblog/env_blog/lib/python3.7/site-packages/flask/app.py", line 1815, in full_dispatch_request
    rv = self.handle_user_exception(e)
  File "/Users/13ob0/projects/flask/myblog/env_blog/lib/python3.7/site-packages/flask/app.py", line 1718, in handle_user_exception
    reraise(exc_type, exc_value, tb)
  File "/Users/13ob0/projects/flask/myblog/env_blog/lib/python3.7/site-packages/flask/_compat.py", line 35, in reraise
    raise value
  File "/Users/13ob0/projects/flask/myblog/env_blog/lib/python3.7/site-packages/flask/app.py", line 1813, in full_dispatch_request
    rv = self.dispatch_request()
  File "/Users/13ob0/projects/flask/myblog/env_blog/lib/python3.7/site-packages/flask/app.py", line 1799, in dispatch_request
    return self.view_functions[rule.endpoint](**req.view_args)
  File "/Users/13ob0/projects/flask/myblog/myblog/blueprints/blog.py", line 26, in index
    return render_template('blog/index.html', pagination=pagination, posts=posts)
  File "/Users/13ob0/projects/flask/myblog/env_blog/lib/python3.7/site-packages/flask/templating.py", line 135, in render_template
    context, ctx.app)
  File "/Users/13ob0/projects/flask/myblog/env_blog/lib/python3.7/site-packages/flask/templating.py", line 117, in _render
    rv = template.render(context)
  File "/Users/13ob0/projects/flask/myblog/env_blog/lib/python3.7/site-packages/jinja2/asyncsupport.py", line 76, in render
    return original_render(self, *args, **kwargs)
  File "/Users/13ob0/projects/flask/myblog/env_blog/lib/python3.7/site-packages/jinja2/environment.py", line 1008, in render
    return self.environment.handle_exception(exc_info, True)
  File "/Users/13ob0/projects/flask/myblog/env_blog/lib/python3.7/site-packages/jinja2/environment.py", line 780, in handle_exception
    reraise(exc_type, exc_value, tb)
  File "/Users/13ob0/projects/flask/myblog/env_blog/lib/python3.7/site-packages/jinja2/_compat.py", line 37, in reraise
    raise value.with_traceback(tb)
  File "/Users/13ob0/projects/flask/myblog/myblog/templates/blog/index.html", line 2, in top-level template code
    {% from 'bootstrap/pagination.html' import render_pager %}
  File "/Users/13ob0/projects/flask/myblog/myblog/templates/base.html", line 81, in top-level template code
    {% block content %}{% endblock content %}
  File "/Users/13ob0/projects/flask/myblog/myblog/templates/blog/index.html", line 19, in block "content"
    {% include 'blog/_sidebar.html' %}
  File "/Users/13ob0/projects/flask/myblog/myblog/templates/blog/_sidebar.html", line 36, in top-level template code
    {% for theme_name, display_name in config.BLUELOG_THEMES.items() %}
  File "/Users/13ob0/projects/flask/myblog/env_blog/lib/python3.7/site-packages/jinja2/environment.py", line 430, in getattr
    return getattr(obj, attribute)
jinja2.exceptions.UndefinedError: 'flask.config.Config object' has no attribute 'BLUELOG_THEMES'
2020-04-21 12:23:02,297 - flask.app - ERROR - Exception on / [GET]
Traceback (most recent call last):
  File "/Users/13ob0/projects/flask/myblog/env_blog/lib/python3.7/site-packages/flask/app.py", line 2292, in wsgi_app
    response = self.full_dispatch_request()
  File "/Users/13ob0/projects/flask/myblog/env_blog/lib/python3.7/site-packages/flask/app.py", line 1815, in full_dispatch_request
    rv = self.handle_user_exception(e)
  File "/Users/13ob0/projects/flask/myblog/env_blog/lib/python3.7/site-packages/flask/app.py", line 1718, in handle_user_exception
    reraise(exc_type, exc_value, tb)
  File "/Users/13ob0/projects/flask/myblog/env_blog/lib/python3.7/site-packages/flask/_compat.py", line 35, in reraise
    raise value
  File "/Users/13ob0/projects/flask/myblog/env_blog/lib/python3.7/site-packages/flask/app.py", line 1813, in full_dispatch_request
    rv = self.dispatch_request()
  File "/Users/13ob0/projects/flask/myblog/env_blog/lib/python3.7/site-packages/flask/app.py", line 1799, in dispatch_request
    return self.view_functions[rule.endpoint](**req.view_args)
  File "/Users/13ob0/projects/flask/myblog/myblog/blueprints/blog.py", line 26, in index
    return render_template('blog/index.html', pagination=pagination, posts=posts)
  File "/Users/13ob0/projects/flask/myblog/env_blog/lib/python3.7/site-packages/flask/templating.py", line 135, in render_template
    context, ctx.app)
  File "/Users/13ob0/projects/flask/myblog/env_blog/lib/python3.7/site-packages/flask/templating.py", line 117, in _render
    rv = template.render(context)
  File "/Users/13ob0/projects/flask/myblog/env_blog/lib/python3.7/site-packages/jinja2/asyncsupport.py", line 76, in render
    return original_render(self, *args, **kwargs)
  File "/Users/13ob0/projects/flask/myblog/env_blog/lib/python3.7/site-packages/jinja2/environment.py", line 1008, in render
    return self.environment.handle_exception(exc_info, True)
  File "/Users/13ob0/projects/flask/myblog/env_blog/lib/python3.7/site-packages/jinja2/environment.py", line 780, in handle_exception
    reraise(exc_type, exc_value, tb)
  File "/Users/13ob0/projects/flask/myblog/env_blog/lib/python3.7/site-packages/jinja2/_compat.py", line 37, in reraise
    raise value.with_traceback(tb)
  File "/Users/13ob0/projects/flask/myblog/myblog/templates/blog/index.html", line 2, in top-level template code
    {% from 'bootstrap/pagination.html' import render_pager %}
  File "/Users/13ob0/projects/flask/myblog/myblog/templates/base.html", line 81, in top-level template code
    {% block content %}{% endblock content %}
  File "/Users/13ob0/projects/flask/myblog/myblog/templates/blog/index.html", line 19, in block "content"
    {% include 'blog/_sidebar.html' %}
  File "/Users/13ob0/projects/flask/myblog/myblog/templates/blog/_sidebar.html", line 36, in top-level template code
    {% for theme_name, display_name in config.BLUELOG_THEMES.items() %}
  File "/Users/13ob0/projects/flask/myblog/env_blog/lib/python3.7/site-packages/jinja2/environment.py", line 430, in getattr
    return getattr(obj, attribute)
jinja2.exceptions.UndefinedError: 'flask.config.Config object' has no attribute 'BLUELOG_THEMES'
2020-04-21 12:23:02,335 - flask.app - ERROR - Exception on / [GET]
Traceback (most recent call last):
  File "/Users/13ob0/projects/flask/myblog/env_blog/lib/python3.7/site-packages/flask/app.py", line 2292, in wsgi_app
    response = self.full_dispatch_request()
  File "/Users/13ob0/projects/flask/myblog/env_blog/lib/python3.7/site-packages/flask/app.py", line 1815, in full_dispatch_request
    rv = self.handle_user_exception(e)
  File "/Users/13ob0/projects/flask/myblog/env_blog/lib/python3.7/site-packages/flask/app.py", line 1718, in handle_user_exception
    reraise(exc_type, exc_value, tb)
  File "/Users/13ob0/projects/flask/myblog/env_blog/lib/python3.7/site-packages/flask/_compat.py", line 35, in reraise
    raise value
  File "/Users/13ob0/projects/flask/myblog/env_blog/lib/python3.7/site-packages/flask/app.py", line 1813, in full_dispatch_request
    rv = self.dispatch_request()
  File "/Users/13ob0/projects/flask/myblog/env_blog/lib/python3.7/site-packages/flask/app.py", line 1799, in dispatch_request
    return self.view_functions[rule.endpoint](**req.view_args)
  File "/Users/13ob0/projects/flask/myblog/myblog/blueprints/blog.py", line 26, in index
    return render_template('blog/index.html', pagination=pagination, posts=posts)
  File "/Users/13ob0/projects/flask/myblog/env_blog/lib/python3.7/site-packages/flask/templating.py", line 135, in render_template
    context, ctx.app)
  File "/Users/13ob0/projects/flask/myblog/env_blog/lib/python3.7/site-packages/flask/templating.py", line 117, in _render
    rv = template.render(context)
  File "/Users/13ob0/projects/flask/myblog/env_blog/lib/python3.7/site-packages/jinja2/asyncsupport.py", line 76, in render
    return original_render(self, *args, **kwargs)
  File "/Users/13ob0/projects/flask/myblog/env_blog/lib/python3.7/site-packages/jinja2/environment.py", line 1008, in render
    return self.environment.handle_exception(exc_info, True)
  File "/Users/13ob0/projects/flask/myblog/env_blog/lib/python3.7/site-packages/jinja2/environment.py", line 780, in handle_exception
    reraise(exc_type, exc_value, tb)
  File "/Users/13ob0/projects/flask/myblog/env_blog/lib/python3.7/site-packages/jinja2/_compat.py", line 37, in reraise
    raise value.with_traceback(tb)
  File "/Users/13ob0/projects/flask/myblog/myblog/templates/blog/index.html", line 2, in top-level template code
    {% from 'bootstrap/pagination.html' import render_pager %}
  File "/Users/13ob0/projects/flask/myblog/myblog/templates/base.html", line 81, in top-level template code
    {% block content %}{% endblock content %}
  File "/Users/13ob0/projects/flask/myblog/myblog/templates/blog/index.html", line 19, in block "content"
    {% include 'blog/_sidebar.html' %}
  File "/Users/13ob0/projects/flask/myblog/myblog/templates/blog/_sidebar.html", line 36, in top-level template code
    {% for theme_name, display_name in config.BLUELOG_THEMES.items() %}
  File "/Users/13ob0/projects/flask/myblog/env_blog/lib/python3.7/site-packages/jinja2/environment.py", line 430, in getattr
    return getattr(obj, attribute)
jinja2.exceptions.UndefinedError: 'flask.config.Config object' has no attribute 'BLUELOG_THEMES'
2020-04-21 12:25:25,965 - flask.app - ERROR - Exception on / [GET]
Traceback (most recent call last):
  File "/Users/13ob0/projects/flask/myblog/env_blog/lib/python3.7/site-packages/flask/app.py", line 2292, in wsgi_app
    response = self.full_dispatch_request()
  File "/Users/13ob0/projects/flask/myblog/env_blog/lib/python3.7/site-packages/flask/app.py", line 1815, in full_dispatch_request
    rv = self.handle_user_exception(e)
  File "/Users/13ob0/projects/flask/myblog/env_blog/lib/python3.7/site-packages/flask/app.py", line 1718, in handle_user_exception
    reraise(exc_type, exc_value, tb)
  File "/Users/13ob0/projects/flask/myblog/env_blog/lib/python3.7/site-packages/flask/_compat.py", line 35, in reraise
    raise value
  File "/Users/13ob0/projects/flask/myblog/env_blog/lib/python3.7/site-packages/flask/app.py", line 1813, in full_dispatch_request
    rv = self.dispatch_request()
  File "/Users/13ob0/projects/flask/myblog/env_blog/lib/python3.7/site-packages/flask/app.py", line 1799, in dispatch_request
    return self.view_functions[rule.endpoint](**req.view_args)
  File "/Users/13ob0/projects/flask/myblog/myblog/blueprints/blog.py", line 26, in index
    return render_template('blog/index.html', pagination=pagination, posts=posts)
  File "/Users/13ob0/projects/flask/myblog/env_blog/lib/python3.7/site-packages/flask/templating.py", line 135, in render_template
    context, ctx.app)
  File "/Users/13ob0/projects/flask/myblog/env_blog/lib/python3.7/site-packages/flask/templating.py", line 117, in _render
    rv = template.render(context)
  File "/Users/13ob0/projects/flask/myblog/env_blog/lib/python3.7/site-packages/jinja2/asyncsupport.py", line 76, in render
    return original_render(self, *args, **kwargs)
  File "/Users/13ob0/projects/flask/myblog/env_blog/lib/python3.7/site-packages/jinja2/environment.py", line 1008, in render
    return self.environment.handle_exception(exc_info, True)
  File "/Users/13ob0/projects/flask/myblog/env_blog/lib/python3.7/site-packages/jinja2/environment.py", line 780, in handle_exception
    reraise(exc_type, exc_value, tb)
  File "/Users/13ob0/projects/flask/myblog/env_blog/lib/python3.7/site-packages/jinja2/_compat.py", line 37, in reraise
    raise value.with_traceback(tb)
  File "/Users/13ob0/projects/flask/myblog/myblog/templates/blog/index.html", line 2, in top-level template code
    {% from 'bootstrap/pagination.html' import render_pager %}
  File "/Users/13ob0/projects/flask/myblog/myblog/templates/base.html", line 81, in top-level template code
    {% block content %}{% endblock content %}
  File "/Users/13ob0/projects/flask/myblog/myblog/templates/blog/index.html", line 19, in block "content"
    {% include 'blog/_sidebar.html' %}
  File "/Users/13ob0/projects/flask/myblog/myblog/templates/blog/_sidebar.html", line 36, in top-level template code
    {% for theme_name, display_name in config.BLUELOG_THEMES.items() %}
  File "/Users/13ob0/projects/flask/myblog/env_blog/lib/python3.7/site-packages/jinja2/environment.py", line 430, in getattr
    return getattr(obj, attribute)
jinja2.exceptions.UndefinedError: 'flask.config.Config object' has no attribute 'BLUELOG_THEMES'
2020-04-21 12:25:26,008 - flask.app - ERROR - Exception on / [GET]
Traceback (most recent call last):
  File "/Users/13ob0/projects/flask/myblog/env_blog/lib/python3.7/site-packages/flask/app.py", line 2292, in wsgi_app
    response = self.full_dispatch_request()
  File "/Users/13ob0/projects/flask/myblog/env_blog/lib/python3.7/site-packages/flask/app.py", line 1815, in full_dispatch_request
    rv = self.handle_user_exception(e)
  File "/Users/13ob0/projects/flask/myblog/env_blog/lib/python3.7/site-packages/flask/app.py", line 1718, in handle_user_exception
    reraise(exc_type, exc_value, tb)
  File "/Users/13ob0/projects/flask/myblog/env_blog/lib/python3.7/site-packages/flask/_compat.py", line 35, in reraise
    raise value
  File "/Users/13ob0/projects/flask/myblog/env_blog/lib/python3.7/site-packages/flask/app.py", line 1813, in full_dispatch_request
    rv = self.dispatch_request()
  File "/Users/13ob0/projects/flask/myblog/env_blog/lib/python3.7/site-packages/flask/app.py", line 1799, in dispatch_request
    return self.view_functions[rule.endpoint](**req.view_args)
  File "/Users/13ob0/projects/flask/myblog/myblog/blueprints/blog.py", line 26, in index
    return render_template('blog/index.html', pagination=pagination, posts=posts)
  File "/Users/13ob0/projects/flask/myblog/env_blog/lib/python3.7/site-packages/flask/templating.py", line 135, in render_template
    context, ctx.app)
  File "/Users/13ob0/projects/flask/myblog/env_blog/lib/python3.7/site-packages/flask/templating.py", line 117, in _render
    rv = template.render(context)
  File "/Users/13ob0/projects/flask/myblog/env_blog/lib/python3.7/site-packages/jinja2/asyncsupport.py", line 76, in render
    return original_render(self, *args, **kwargs)
  File "/Users/13ob0/projects/flask/myblog/env_blog/lib/python3.7/site-packages/jinja2/environment.py", line 1008, in render
    return self.environment.handle_exception(exc_info, True)
  File "/Users/13ob0/projects/flask/myblog/env_blog/lib/python3.7/site-packages/jinja2/environment.py", line 780, in handle_exception
    reraise(exc_type, exc_value, tb)
  File "/Users/13ob0/projects/flask/myblog/env_blog/lib/python3.7/site-packages/jinja2/_compat.py", line 37, in reraise
    raise value.with_traceback(tb)
  File "/Users/13ob0/projects/flask/myblog/myblog/templates/blog/index.html", line 2, in top-level template code
    {% from 'bootstrap/pagination.html' import render_pager %}
  File "/Users/13ob0/projects/flask/myblog/myblog/templates/base.html", line 81, in top-level template code
    {% block content %}{% endblock content %}
  File "/Users/13ob0/projects/flask/myblog/myblog/templates/blog/index.html", line 19, in block "content"
    {% include 'blog/_sidebar.html' %}
  File "/Users/13ob0/projects/flask/myblog/myblog/templates/blog/_sidebar.html", line 36, in top-level template code
    {% for theme_name, display_name in config.BLUELOG_THEMES.items() %}
  File "/Users/13ob0/projects/flask/myblog/env_blog/lib/python3.7/site-packages/jinja2/environment.py", line 430, in getattr
    return getattr(obj, attribute)
jinja2.exceptions.UndefinedError: 'flask.config.Config object' has no attribute 'BLUELOG_THEMES'
2020-04-21 12:25:26,047 - flask.app - ERROR - Exception on / [GET]
Traceback (most recent call last):
  File "/Users/13ob0/projects/flask/myblog/env_blog/lib/python3.7/site-packages/flask/app.py", line 2292, in wsgi_app
    response = self.full_dispatch_request()
  File "/Users/13ob0/projects/flask/myblog/env_blog/lib/python3.7/site-packages/flask/app.py", line 1815, in full_dispatch_request
    rv = self.handle_user_exception(e)
  File "/Users/13ob0/projects/flask/myblog/env_blog/lib/python3.7/site-packages/flask/app.py", line 1718, in handle_user_exception
    reraise(exc_type, exc_value, tb)
  File "/Users/13ob0/projects/flask/myblog/env_blog/lib/python3.7/site-packages/flask/_compat.py", line 35, in reraise
    raise value
  File "/Users/13ob0/projects/flask/myblog/env_blog/lib/python3.7/site-packages/flask/app.py", line 1813, in full_dispatch_request
    rv = self.dispatch_request()
  File "/Users/13ob0/projects/flask/myblog/env_blog/lib/python3.7/site-packages/flask/app.py", line 1799, in dispatch_request
    return self.view_functions[rule.endpoint](**req.view_args)
  File "/Users/13ob0/projects/flask/myblog/myblog/blueprints/blog.py", line 26, in index
    return render_template('blog/index.html', pagination=pagination, posts=posts)
  File "/Users/13ob0/projects/flask/myblog/env_blog/lib/python3.7/site-packages/flask/templating.py", line 135, in render_template
    context, ctx.app)
  File "/Users/13ob0/projects/flask/myblog/env_blog/lib/python3.7/site-packages/flask/templating.py", line 117, in _render
    rv = template.render(context)
  File "/Users/13ob0/projects/flask/myblog/env_blog/lib/python3.7/site-packages/jinja2/asyncsupport.py", line 76, in render
    return original_render(self, *args, **kwargs)
  File "/Users/13ob0/projects/flask/myblog/env_blog/lib/python3.7/site-packages/jinja2/environment.py", line 1008, in render
    return self.environment.handle_exception(exc_info, True)
  File "/Users/13ob0/projects/flask/myblog/env_blog/lib/python3.7/site-packages/jinja2/environment.py", line 780, in handle_exception
    reraise(exc_type, exc_value, tb)
  File "/Users/13ob0/projects/flask/myblog/env_blog/lib/python3.7/site-packages/jinja2/_compat.py", line 37, in reraise
    raise value.with_traceback(tb)
  File "/Users/13ob0/projects/flask/myblog/myblog/templates/blog/index.html", line 2, in top-level template code
    {% from 'bootstrap/pagination.html' import render_pager %}
  File "/Users/13ob0/projects/flask/myblog/myblog/templates/base.html", line 81, in top-level template code
    {% block content %}{% endblock content %}
  File "/Users/13ob0/projects/flask/myblog/myblog/templates/blog/index.html", line 19, in block "content"
    {% include 'blog/_sidebar.html' %}
  File "/Users/13ob0/projects/flask/myblog/myblog/templates/blog/_sidebar.html", line 36, in top-level template code
    {% for theme_name, display_name in config.BLUELOG_THEMES.items() %}
  File "/Users/13ob0/projects/flask/myblog/env_blog/lib/python3.7/site-packages/jinja2/environment.py", line 430, in getattr
    return getattr(obj, attribute)
jinja2.exceptions.UndefinedError: 'flask.config.Config object' has no attribute 'BLUELOG_THEMES'
